Workbook

Sheet Lisez-moi
A1: Campagne de calibration — banc de charge par génératrice
A2: Stage GEN5001 · Bekobo Nguedi Ariel Toussaint · UQO
A4: Contenu du classeur
A5: Données brutes — les dix séries d'origine, remises en colonnes appariées par palier.
A6: Séries établies — mêmes séries après retrait de la phase de démarrage.
A7: Synthèse — moyenne, écart-type et plage ±2σ par palier (formules Excel).
A8: Dérive — évolution du courant au cours de chaque acquisition.
A10: Règle de sélection appliquée
A11: Chaque série d'origine contient une phase de démarrage (valeurs nulles moteur à l'arrêt, puis
A12: montée en régime). Cette phase a été retirée de façon uniforme : on écarte les valeurs nulles,
A13: puis tous les échantillons antérieurs au premier qui atteint 95 % de la médiane des cent
A14: derniers échantillons de la série. Le reste constitue la période établie.
... A25: courant dépendent donc de la fenêtre retenue, ce qui n'est pas le cas de la vitesse.

Sheet Données brutes
A1: Séries d'origine, réorganisées par palier (courant converti en mA)
A3: P1 — Circuit ouvert | D3: P2 — 220 Ω | G3: P3 — 100 Ω | J3: P4 — 51 Ω | M3: P5 — 33,33 Ω
A4: Vitesse (tr/min) | B4: Courant (mA) | D4: Vitesse (tr/min) | E4: Courant (mA) | G4: Vitesse (tr/min) | H4: Courant (mA) | J4: Vitesse (tr/min) | K4: Courant (mA) | M4: Vitesse (tr/min) | N4: Courant (mA)
A5: 0 | B5: 0 | D5: 157.5 | E5: 500 | G5: 110 | H5: 500 | J5: 76.6 | K5: 400 | M5: 58.2 | N5: 400
A6: 0 | B6: 0 | D6: 158.8 | E6: 500 | G6: 109.6 | H6: 500 | J6: 76.6 | K6: 400 | M6: 58.6 | N6: 400
A7: 0 | B7: 0 | D7: 159.7 | E7: 500 | G7: 109.2 | H7: 500 | J7: 77.1 | K7: 500 | M7: 59.1 | N7: 400
A8: 0 | B8: 0 | D8: 157.5 | E8: 500 | G8: 110.4 | H8: 500 | J8: 75.8 | K8: 400 | M8: 58.6 | N8: 400
A9: 0 | B9: 0 | D9: 159.7 | E9: 500 | G9: 110.9 | H9: 500 | J9: 77.1 | K9: 300 | M9: 58.6 | N9: 400
A10: 0 | B10: 0 | D10: 158.4 | E10: 500 | G10: 110 | H10: 600 | J10: 76.6 | K10: 400 | M10: 59.1 | N10: 600
A11: 0 | B11: 0 | D11: 158 | E11: 500 | G11: 110.4 | H11: 500 | J11: 76.2 | K11: 500 | M11: 58.2 | N11: 200
A12: 0 | B12: 0 | D12: 159.7 | E12: 500 | G12: 110.4 | H12: 500 | J12: 77.1 | K12: 300 | M12: 58.6 | N12: 400
A13: 0 | B13: 0 | D13: 158.8 | E13: 500 | G13: 109.2 | H13: 500 | J13: 76.6 | K13: 400 | M13: 58.2 | N13: 400
A14: 0 | B14: 0 | D14: 157.5 | E14: 500 | G14: 111.3 | H14: 600 | J14: 76.2 | K14: 500 | M14: 58.2 | N14: 500
A15: 0 | B15: 0 | D15: 159.7 | E15: 500 | G15: 109.8 | H15: 500 | J15: 76.2 | K15: 400 | M15: 59.1 | N15: 300
A16: 0 | B16: 0 | D16: 158.1 | E16: 500 | G16: 111.3 | H16: 600 | J16: 76.6 | K16: 500 | M16: 58.6 | N16: 400
... A544: 229.5 | B544: 500 | D544: 161 | E544: 700 | G544: 113 | H544: 600 | J544: 75.3 | K544: 500 | M544: 58.6 | N544: 700
A545: 231.6 | B545: 600 | D545: 160.1 | E545: 700 | H545: 500 | J545: 75.3 | K545: 600 | M545: 57.8 | N545: 800
A546: 232.9 | B546: 600 | D546: 159.7 | E546: 700 | H546: 500 | J546: 74.9 | K546: 500 | M546: 57.8 | N546: 800
A547: 229.5 | B547: 500 | D547: 160.5 | E547: 700 | H547: 500 | J547: 74.9 | K547: 500 | M547: 58.2 | N547: 600
A548: 231.6 | B548: 500 | D548: 160.5 | E548: 700 | H548: 600 | J548: 75.3 | K548: 500 | M548: 57.8 | N548: 500
A549: 232.4 | B549: 500 | D549: 160.1 | E549: 600 | H549: 500 | J549: 74.9 | K549: 600 | M549: 56.9 | N549: 500
A550: 229.5 | B550: 600 | D550: 160.5 | E550: 700 | H550: 600 | J550: 74.9 | K550: 500 | M550: 57.8 | N550: 600
A551: 232.9 | B551: 600 | D551: 160.5 | E551: 700 | H551: 500 | J551: 75.3 | K551: 500 | M551: 58.2 | N551: 600
A552: 232 | B552: 500 | D552: 159.2 | E552: 600 | H552: 500 | J552: 74.9 | K552: 500 | M552: 57.8 | N552: 700
A553: 229.5 | B553: 600 | D553: 161.4 | E553: 700 | H553: 500 | J553: 74.9 | K553: 600 | M553: 58.2 | N553: 600
A554: 232.4 | B554: 600 | D554: 158.8 | E554: 700 | H554: 500 | J554: 75.3 | K554: 500 | M554: 58.6 | N554: 700
A555: 229.9 | B555: 500 | D555: 161 | E555: 600 | H555: 500 | J555: 74.9 | K555: 500 | M555: 57.4 | N555: 700
A556: 232 | B556: 500 | D556: 161.4 | E556: 600 | H556: 500 | J556: 74.5 | K556: 500 | M556: 58.2 | N556: 700
... A562: 232.9 | B562: 500 | D562: 161 | E562: 700 | H562: 500 | J562: 75.3 | K562: 500 | M562: 57.8 | N562: 800
A563: 232.4 | B563: 500 | D563: 159.2 | E563: 700 | H563: 500 | J563: 74.5 | M563: 58.2 | N563: 700
A564: 230.3 | B564: 500 | D564: 161.4 | E564: 700 | H564: 500 | J564: 74.9 | M564: 58.2 | N564: 700
A565: 232.4 | B565: 500 | D565: 161.4 | E565: 700 | H565: 500 | J565: 75.8 | M565: 58.2 | N565: 700
A566: 232.4 | B566: 600 | D566: 158.8 | E566: 700 | H566: 500 | J566: 74.1 | M566: 57.4 | N566: 800
A567: 230.7 | B567: 500 | D567: 161.8 | E567: 600 | H567: 500 | J567: 75.3 | M567: 58.2 | N567: 800
A568: 231.6 | B568: 500 | D568: 161 | E568: 700 | H568: 500 | J568: 75.3 | M568: 58.2 | N568: 700
A569: 232.9 | B569: 500 | D569: 159.7 | E569: 600 | H569: 500 | J569: 74.9 | M569: 56.9 | N569: 700
A570: 230.7 | B570: 500 | D570: 161 | E570: 600 | H570: 500 | J570: 74.9 | M570: 57.8 | N570: 700
A571: 232.4 | B571: 500 | D571: 161.4 | E571: 700 | H571: 500 | J571: 75.3 | M571: 57.8 | N571: 700
A572: 232.9 | B572: 500 | D572: 159.7 | E572: 700 | H572: 500 | J572: 74.1 | M572: 57.8 | N572: 800
A573: 229.9 | B573: 500 | D573: 161 | E573: 600 | H573: 500 | J573: 74.9 | M573: 57.8 | N573: 700
...

Sheet Séries établies
A1: Séries après retrait de la phase de démarrage (règle décrite dans « Lisez-moi »)
A3: P1 — Circuit ouvert | D3: P2 — 220 Ω | G3: P3 — 100 Ω | J3: P4 — 51 Ω | M3: P5 — 33,33 Ω
A4: Vitesse (tr/min) | B4: Courant (mA) | D4: Vitesse (tr/min) | E4: Courant (mA) | G4: Vitesse (tr/min) | H4: Courant (mA) | J4: Vitesse (tr/min) | K4: Courant (mA) | M4: Vitesse (tr/min) | N4: Courant (mA)
A5: 220.5 | B5: 600 | D5: 157.5 | E5: 600 | G5: 110 | H5: 500 | J5: 76.6 | K5: 500 | M5: 58.2 | N5: 700
A6: 219.6 | B6: 500 | D6: 158.8 | E6: 500 | G6: 109.6 | H6: 500 | J6: 76.6 | K6: 400 | M6: 58.6 | N6: 600
A7: 218.8 | B7: 500 | D7: 159.7 | E7: 500 | G7: 109.2 | H7: 500 | J7: 77.1 | K7: 300 | M7: 59.1 | N7: 700
A8: 220.9 | B8: 600 | D8: 157.5 | E8: 600 | G8: 110.4 | H8: 500 | J8: 75.8 | K8: 400 | M8: 58.6 | N8: 700
A9: 220 | B9: 500 | D9: 159.7 | E9: 600 | G9: 110.9 | H9: 500 | J9: 77.1 | K9: 500 | M9: 58.6 | N9: 700
A10: 219.2 | B10: 500 | D10: 158.4 | E10: 500 | G10: 110 | H10: 600 | J10: 76.6 | K10: 300 | M10: 59.1 | N10: 500
A11: 220.5 | B11: 500 | D11: 158 | E11: 600 | G11: 110.4 | H11: 500 | J11: 76.2 | K11: 400 | M11: 58.2 | N11: 200
A12: 220.9 | B12: 500 | D12: 159.7 | E12: 500 | G12: 110.4 | H12: 500 | J12: 77.1 | K12: 500 | M12: 58.6 | N12: 300
A13: 219.2 | B13: 600 | D13: 158.8 | E13: 600 | G13: 109.2 | H13: 500 | J13: 76.6 | K13: 400 | M13: 58.2 | N13: 200
A14: 221.3 | B14: 500 | D14: 157.5 | E14: 600 | G14: 111.3 | H14: 600 | J14: 76.2 | K14: 500 | M14: 58.2 | N14: 600
A15: 222.2 | B15: 500 | D15: 159.7 | E15: 600 | G15: 109.8 | H15: 500 | J15: 76.2 | K15: 200 | M15: 59.1 | N15: 700
A16: 219.2 | B16: 600 | D16: 158.1 | E16: 600 | G16: 111.3 | H16: 600 | J16: 76.6 | K16: 400 | M16: 58.6 | N16: 400
... A419: 232.4 | B419: 500 | D419: 160.1 | E419: 600 | G419: 112.6 | H419: 500 | J419: 74.9 | K419: 500 | M419: 58.6 | N419: 800
B420: 500 | D420: 160.1 | E420: 600 | G420: 111.7 | H420: 500 | J420: 75.3 | K420: 500 | M420: 57.8 | N420: 600
B421: 600 | D421: 158 | E421: 600 | G421: 113 | H421: 500 | J421: 74.5 | K421: 500 | M421: 57.8 | N421: 500
B422: 500 | D422: 161 | E422: 600 | G422: 112.6 | H422: 500 | J422: 75.3 | K422: 500 | M422: 58.2 | N422: 600
B423: 500 | D423: 160.1 | E423: 600 | G423: 111.7 | H423: 500 | J423: 74.9 | K423: 500 | M423: 58.2 | N423: 600
B424: 500 | D424: 158 | E424: 700 | G424: 112.6 | H424: 500 | J424: 74.9 | K424: 600 | M424: 57.4 | N424: 700
B425: 600 | D425: 160.1 | E425: 600 | G425: 113 | H425: 500 | J425: 75.3 | K425: 500 | M425: 57.8 | N425: 700
B426: 600 | D426: 159.2 | E426: 700 | G426: 111.7 | H426: 500 | J426: 75.3 | K426: 500 | M426: 58.2 | N426: 500
B427: 500 | D427: 160.1 | E427: 600 | G427: 113 | H427: 500 | J427: 74.5 | K427: 500 | M427: 57.4 | N427: 400
B428: 600 | D428: 159.7 | E428: 600 | G428: 113 | H428: 500 | J428: 75.3 | K428: 500 | M428: 58.6 | N428: 400
B429: 600 | D429: 159.2 | E429: 600 | G429: 111.3 | H429: 500 | J429: 74.9 | K429: 500 | M429: 58.2 | N429: 500
B430: 500 | D430: 159.7 | E430: 600 | G430: 113 | H430: 500 | J430: 74.5 | K430: 500 | M430: 58.2 | N430: 700
B431: 500 | D431: 160.5 | E431: 600 | G431: 112.2 | H431: 500 | J431: 75.8 | K431: 500 | M431: 57.8 | N431: 500
... B544: 500 | D544: 161 | E544: 600 | G544: 113 | H544: 600 | J544: 75.3 | K544: 500 | M544: 58.6 | N544: 700
B545: 500 | D545: 160.1 | E545: 700 | H545: 500 | J545: 75.3 | K545: 500 | M545: 57.8 | N545: 700
B546: 500 | D546: 159.7 | E546: 700 | H546: 500 | J546: 74.9 | K546: 500 | M546: 57.8 | N546: 700
B547: 500 | D547: 160.5 | E547: 600 | H547: 500 | J547: 74.9 | K547: 600 | M547: 58.2 | N547: 800
B548: 600 | D548: 160.5 | E548: 700 | H548: 600 | J548: 75.3 | K548: 500 | M548: 57.8 | N548: 700
B549: 500 | D549: 160.1 | E549: 700 | H549: 500 | J549: 74.9 | K549: 500 | M549: 56.9 | N549: 700
B550: 500 | D550: 160.5 | E550: 700 | H550: 600 | J550: 74.9 | K550: 500 | M550: 57.8 | N550: 700
B551: 500 | D551: 160.5 | E551: 700 | H551: 500 | J551: 75.3 | K551: 600 | M551: 58.2 | N551: 800
B552: 500 | D552: 159.2 | E552: 700 | H552: 500 | J552: 74.9 | K552: 500 | M552: 57.8 | N552: 800
B553: 500 | D553: 161.4 | E553: 700 | H553: 500 | J553: 74.9 | K553: 500 | M553: 58.2 | N553: 700
B554: 500 | D554: 158.8 | E554: 600 | H554: 500 | J554: 75.3 | K554: 500 | M554: 58.6 | N554: 700
B555: 500 | D555: 161 | E555: 700 | H555: 500 | J555: 74.9 | K555: 600 | M555: 57.4 | N555: 700
...

Sheet Synthèse
A1: Synthèse statistique par palier
A2: Calculée par formules sur l'onglet « Séries établies ». Écart-type sur échantillon (correction de Bessel).
A4: Palier | B4: Charge | C4: R (Ω) | D4: n vitesse | E4: Vitesse moy. (tr/min) | F4: σ vitesse | G4: Plage ±2σ vitesse | H4: n courant | I4: Courant moy. (mA) | J4: σ courant | K4: Plage ±2σ courant
A5: P1 | B5: Circuit ouvert | C5: — | D5: =COUNT('Séries établies'!$A$5:$A$419) -> 415 | E5: =AVERAGE('Séries établies'!$A$5:$A$419) -> 227.52747 | F5: =STDEV('Séries établies'!$A$5:$A$419) -> 3.134939 | G5: =TEXT(E5-2*F5,"0.0")&" – "&TEXT(E5+2*F5,"0.0") -> 221.3 – 233.8 | H5: =COUNT('Séries établies'!$B$5:$B$586) -> 582 | I5: =AVERAGE('Séries établies'!$B$5:$B$586) -> 532.64605 | J5: =STDEV('Séries établies'!$B$5:$B$586) -> 47.297445 | K5: =TEXT(I5-2*J5,"0")&" – "&TEXT(I5+2*J5,"0") -> 438 – 627
A6: P2 | B6: 220 Ω | C6: 220 | D6: =COUNT('Séries établies'!$D$5:$D$603) -> 599 | E6: =AVERAGE('Séries établies'!$D$5:$D$603) -> 159.49633 | F6: =STDEV('Séries établies'!$D$5:$D$603) -> 1.0818601 | G6: =TEXT(E6-2*F6,"0.0")&" – "&TEXT(E6+2*F6,"0.0") -> 157.3 – 161.7 | H6: =COUNT('Séries établies'!$E$5:$E$573) -> 569 | I6: =AVERAGE('Séries établies'!$E$5:$E$573) -> 534.4464 | J6: =STDEV('Séries établies'!$E$5:$E$573) -> 96.823226 | K6: =TEXT(I6-2*J6,"0")&" – "&TEXT(I6+2*J6,"0") -> 341 – 728
A7: P3 | B7: 100 Ω | C7: 100 | D7: =COUNT('Séries établies'!$G$5:$G$544) -> 540 | E7: =AVERAGE('Séries établies'!$G$5:$G$544) -> 112.17407 | F7: =STDEV('Séries établies'!$G$5:$G$544) -> 0.79014927 | G7: =TEXT(E7-2*F7,"0.0")&" – "&TEXT(E7+2*F7,"0.0") -> 110.6 – 113.8 | H7: =COUNT('Séries établies'!$H$5:$H$577) -> 573 | I7: =AVERAGE('Séries établies'!$H$5:$H$577) -> 508.20244 | J7: =STDEV('Séries établies'!$H$5:$H$577) -> 27.46417 | K7: =TEXT(I7-2*J7,"0")&" – "&TEXT(I7+2*J7,"0") -> 453 – 563
A8: P4 | B8: 51 Ω | C8: 51 | D8: =COUNT('Séries établies'!$J$5:$J$603) -> 599 | E8: =AVERAGE('Séries établies'!$J$5:$J$603) -> 75.425042 | F8: =STDEV('Séries établies'!$J$5:$J$603) -> 0.63488915 | G8: =TEXT(E8-2*F8,"0.0")&" – "&TEXT(E8+2*F8,"0.0") -> 74.2 – 76.7 | H8: =COUNT('Séries établies'!$K$5:$K$560) -> 556 | I8: =AVERAGE('Séries établies'!$K$5:$K$560) -> 510.07194 | J8: =STDEV('Séries établies'!$K$5:$K$560) -> 63.580794 | K8: =TEXT(I8-2*J8,"0")&" – "&TEXT(I8+2*J8,"0") -> 383 – 637
A9: P5 | B9: 33,33 Ω | C9: 33.33 | D9: =COUNT('Séries établies'!$M$5:$M$603) -> 599 | E9: =AVERAGE('Séries établies'!$M$5:$M$603) -> 58.112354 | F9: =STDEV('Séries établies'!$M$5:$M$603) -> 0.47725627 | G9: =TEXT(E9-2*F9,"0.0")&" – "&TEXT(E9+2*F9,"0.0") -> 57.2 – 59.1 | H9: =COUNT('Séries établies'!$N$5:$N$558) -> 554 | I9: =AVERAGE('Séries établies'!$N$5:$N$558) -> 564.07942 | J9: =STDEV('Séries établies'!$N$5:$N$558) -> 150.55762 | K9: =TEXT(I9-2*J9,"0")&" – "&TEXT(I9+2*J9,"0") -> 263 – 865
A11: Lecture
A12: La vitesse décroît de façon strictement monotone quand la résistance de charge diminue, et les plages ±2σ des cinq paliers sont disjointes :
A13: la vitesse discrimine sans ambiguïté les cinq niveaux de charge.
A14: Le courant, lui, ne varie pas de façon monotone et les plages ±2σ des cinq paliers se recouvrent toutes. Avec cette acquisition, le courant seul
A15: ne permet donc pas de distinguer les niveaux de charge. Voir l'onglet « Dérive » pour l'explication probable.

Sheet Dérive
A1: Dérive du courant au cours de chaque acquisition
A2: Moyenne du courant (mA) calculée par tranches successives de 60 échantillons, soit 6 secondes à 10 Hz.
A4: Tranche | B4: P1 (Circuit ouvert) | C4: P2 (220 Ω) | D4: P3 (100 Ω) | E4: P4 (51 Ω) | F4: P5 (33,33 Ω)
A5: 0–6 s | B5: 525 | C5: 495 | D5: 512 | E5: 428 | F5: 575
A6: 6–12 s | B6: 545 | C6: 413 | D6: 508 | E6: 503 | F6: 572
A7: 12–18 s | B7: 548 | C7: 427 | D7: 507 | E7: 515 | F7: 540
A8: 18–24 s | B8: 537 | C8: 480 | D8: 503 | E8: 493 | F8: 508
A9: 24–30 s | B9: 528 | C9: 535 | D9: 502 | E9: 495 | F9: 528
A10: 30–36 s | B10: 527 | C10: 550 | D10: 513 | E10: 538 | F10: 415
A11: 36–42 s | B11: 525 | C11: 600 | D11: 508 | E11: 550 | F11: 590
A12: 42–48 s | B12: 535 | C12: 618 | D12: 510 | E12: 523 | F12: 630
A13: 48–54 s | B13: 532 | C13: 632 | D13: 512 | E13: 542 | F13: 680
A14: 54–60 s | B14: 521 | C14: 659 | D14: 506 | E14: 519 | F14: 729
A16: Pente (mA/min) | B16: -13.2 | C16: 263.5 | D16: 1 | E16: 99.1 | F16: 122.4
A18: Une pente marquée signifie que la moyenne du courant dépend de la fenêtre d'acquisition retenue, ce qui rend
A19: les paliers non comparables entre eux. Les cases orangées signalent une dérive supérieure à 50 mA/min.
